Workbook

Sheet Customer Names
A1: Customer ID | B1: name | C1: Title | D1: First Name | E1: Last Name
A2: Id1 | B2: Hawks, Ms. Kelly | C2: Ms. Kelly Hawks | D2: Ms. Kelly | E2: Hawks
A3: Id2 | B3: Lehner, Mr. Matthew D | C3: Mr. Matthew D Lehner | D3: Mr. Matthew D | E3: Lehner
A4: Id3 | B4: Lu, Mr. Phil | C4: Mr. Phil Lu | D4: Mr. Phil | E4: Lu
A5: Id4 | B5: Osborne, Ms. Kelsey | C5: Ms. Kelsey Osborne | D5: Ms. Kelsey | E5: Osborne
A6: Id5 | B6: Kadala, Ms. Kristyn | C6: Ms. Kristyn Kadala | D6: Ms. Kristyn | E6: Kadala
A7: Id6 | B7: Baker, Mr. Russell B. | C7: Mr. Russell B. Baker | D7: Mr. Russell B. | E7: Baker
A8: Id7 | B8: Macpherson, Mr. Scott | C8: Mr. Scott Macpherson | D8: Mr. Scott | E8: Macpherson
A9: Id8 | B9: Hallman, Mr. Stephen | C9: Mr. Stephen Hallman | D9: Mr. Stephen | E9: Hallman
A10: Id9 | B10: Moran, Mr. Patrick R. | C10: Mr. Patrick R. Moran | D10: Mr. Patrick R. | E10: Moran
A11: Id10 | B11: Benner, Ms. Brooke N. | C11: Ms. Brooke N. Benner | D11: Ms. Brooke N. | E11: Benner
A12: Id11 | B12: Fierro Vargas, Ms. Paola Andrea | C12: Ms. Paola Andrea Fierro Vargas | D12: Ms. Paola Andrea | E12: Fierro Vargas
... A2336: Id2335 | B2336: German, Mr. Aaron K | C2336: Mr. Aaron K German | D2336: Mr. Aaron K | E2336: German

Sheet Medical Examinations
A1: Customer ID | B1: BMI | C1: HBA1C | D1: Heart Issues | E1: Any Transplants | F1: Cancer history | G1: NumberOfMajorSurgeries | H1: Smoker | I1: Weight Status | J1: Diabetes Status
A2: Id1 | B2: 47.41 | C2: 7.47 | D2: No | E2: No | F2: No | G2: 0 | H2: Yes | I2: {=_xlfn.IFS(B2<18.5,"Underweight",AND(B2>=18.5,B2<=24.99),"Normalweight",AND(B2>=25,B2<=29.99),"Overweight",B2>=30,"Obesity")} -> Obesity | J2: {=_xlfn.IFS(C2<5.7,"Normal",AND(C2>=5.7,C2<=6.49),"Prediabetes",C2>=6.5,"Diabetes")} -> Diabetes
A3: Id2 | B3: 30.36 | C3: 5.77 | D3: No | E3: No | F3: No | G3: 0 | H3: Yes | I3: {=_xlfn.IFS(B3<18.5,"Underweight",AND(B3>=18.5,B3<=24.99),"Normalweight",AND(B3>=25,B3<=29.99),"Overweight",B3>=30,"Obesity")} -> Obesity | J3: {=_xlfn.IFS(C3<5.7,"Normal",AND(C3>=5.7,C3<=6.49),"Prediabetes",C3>=6.5,"Diabetes")} -> Prediabetes | L3: =IF(18.5<B2>24.9,"Normalweight") -> Normalweight
A4: Id3 | B4: 34.485 | C4: 11.87 | D4: Yes | E4: No | F4: No | G4: 2 | H4: Yes | I4: {=_xlfn.IFS(B4<18.5,"Underweight",AND(B4>=18.5,B4<=24.99),"Normalweight",AND(B4>=25,B4<=29.99),"Overweight",B4>=30,"Obesity")} -> Obesity | J4: {=_xlfn.IFS(C4<5.7,"Normal",AND(C4>=5.7,C4<=6.49),"Prediabetes",C4>=6.5,"Diabetes")} -> Diabetes | L4: =IF(B2<18.5,"Underweight") -> FALSE
A5: Id4 | B5: 38.095 | C5: 6.05 | D5: No | E5: No | F5: No | G5: 0 | H5: Yes | I5: {=_xlfn.IFS(B5<18.5,"Underweight",AND(B5>=18.5,B5<=24.99),"Normalweight",AND(B5>=25,B5<=29.99),"Overweight",B5>=30,"Obesity")} -> Obesity | J5: {=_xlfn.IFS(C5<5.7,"Normal",AND(C5>=5.7,C5<=6.49),"Prediabetes",C5>=6.5,"Diabetes")} -> Prediabetes
A6: Id5 | B6: 35.53 | C6: 5.45 | D6: No | E6: No | F6: No | G6: 0 | H6: Yes | I6: {=_xlfn.IFS(B6<18.5,"Underweight",AND(B6>=18.5,B6<=24.99),"Normalweight",AND(B6>=25,B6<=29.99),"Overweight",B6>=30,"Obesity")} -> Obesity | J6: {=_xlfn.IFS(C6<5.7,"Normal",AND(C6>=5.7,C6<=6.49),"Prediabetes",C6>=6.5,"Diabetes")} -> Normal
A7: Id6 | B7: 32.8 | C7: 6.59 | D7: No | E7: No | F7: No | G7: 0 | H7: Yes | I7: {=_xlfn.IFS(B7<18.5,"Underweight",AND(B7>=18.5,B7<=24.99),"Normalweight",AND(B7>=25,B7<=29.99),"Overweight",B7>=30,"Obesity")} -> Obesity | J7: {=_xlfn.IFS(C7<5.7,"Normal",AND(C7>=5.7,C7<=6.49),"Prediabetes",C7>=6.5,"Diabetes")} -> Diabetes | M7: {=IFS} -> #NAME?
A8: Id7 | B8: 36.4 | C8: 6.07 | D8: No | E8: No | F8: No | G8: 0 | H8: Yes | I8: {=_xlfn.IFS(B8<18.5,"Underweight",AND(B8>=18.5,B8<=24.99),"Normalweight",AND(B8>=25,B8<=29.99),"Overweight",B8>=30,"Obesity")} -> Obesity | J8: {=_xlfn.IFS(C8<5.7,"Normal",AND(C8>=5.7,C8<=6.49),"Prediabetes",C8>=6.5,"Diabetes")} -> Prediabetes
A9: Id8 | B9: 36.96 | C9: 7.93 | D9: No | E9: No | F9: No | G9: 3 | H9: Yes | I9: {=_xlfn.IFS(B9<18.5,"Underweight",AND(B9>=18.5,B9<=24.99),"Normalweight",AND(B9>=25,B9<=29.99),"Overweight",B9>=30,"Obesity")} -> Obesity | J9: {=_xlfn.IFS(C9<5.7,"Normal",AND(C9>=5.7,C9<=6.49),"Prediabetes",C9>=6.5,"Diabetes")} -> Diabetes
A10: Id9 | B10: 41.14 | C10: 9.58 | D10: Yes | E10: No | F10: Yes | G10: 1 | H10: Yes | I10: {=_xlfn.IFS(B10<18.5,"Underweight",AND(B10>=18.5,B10<=24.99),"Normalweight",AND(B10>=25,B10<=29.99),"Overweight",B10>=30,"Obesity")} -> Obesity | J10: {=_xlfn.IFS(C10<5.7,"Normal",AND(C10>=5.7,C10<=6.49),"Prediabetes",C10>=6.5,"Diabetes")} -> Diabetes
A11: Id10 | B11: 38.06 | C11: 10.79 | D11: No | E11: No | F11: No | G11: 0 | H11: Yes | I11: {=_xlfn.IFS(B11<18.5,"Underweight",AND(B11>=18.5,B11<=24.99),"Normalweight",AND(B11>=25,B11<=29.99),"Overweight",B11>=30,"Obesity")} -> Obesity | J11: {=_xlfn.IFS(C11<5.7,"Normal",AND(C11>=5.7,C11<=6.49),"Prediabetes",C11>=6.5,"Diabetes")} -> Diabetes
A12: Id11 | B12: 37.7 | C12: 5.96 | D12: Yes | E12: No | F12: No | G12: 2 | H12: Yes | I12: {=_xlfn.IFS(B12<18.5,"Underweight",AND(B12>=18.5,B12<=24.99),"Normalweight",AND(B12>=25,B12<=29.99),"Overweight",B12>=30,"Obesity")} -> Obesity | J12: {=_xlfn.IFS(C12<5.7,"Normal",AND(C12>=5.7,C12<=6.49),"Prediabetes",C12>=6.5,"Diabetes")} -> Prediabetes
A13: Id12 | B13: 42.13 | C13: 11.9 | D13: No | E13: No | F13: No | G13: 0 | H13: Yes | I13: {=_xlfn.IFS(B13<18.5,"Underweight",AND(B13>=18.5,B13<=24.99),"Normalweight",AND(B13>=25,B13<=29.99),"Overweight",B13>=30,"Obesity")} -> Obesity | J13: {=_xlfn.IFS(C13<5.7,"Normal",AND(C13>=5.7,C13<=6.49),"Prediabetes",C13>=6.5,"Diabetes")} -> Diabetes
A14: Id13 | B14: 40.92 | C14: 8.41 | D14: No | E14: No | F14: No | G14: 0 | H14: Yes | I14: {=_xlfn.IFS(B14<18.5,"Underweight",AND(B14>=18.5,B14<=24.99),"Normalweight",AND(B14>=25,B14<=29.99),"Overweight",B14>=30,"Obesity")} -> Obesity | J14: {=_xlfn.IFS(C14<5.7,"Normal",AND(C14>=5.7,C14<=6.49),"Prediabetes",C14>=6.5,"Diabetes")} -> Diabetes
A15: Id14 | B15: 40.565 | C15: 7.02 | D15: No | E15: No | F15: No | G15: 0 | H15: Yes | I15: {=_xlfn.IFS(B15<18.5,"Underweight",AND(B15>=18.5,B15<=24.99),"Normalweight",AND(B15>=25,B15<=29.99),"Overweight",B15>=30,"Obesity")} -> Obesity | J15: {=_xlfn.IFS(C15<5.7,"Normal",AND(C15>=5.7,C15<=6.49),"Prediabetes",C15>=6.5,"Diabetes")} -> Diabetes
A16: Id15 | B16: 36.385 | C16: 7.59 | D16: Yes | E16: No | F16: No | G16: 2 | H16: Yes | I16: {=_xlfn.IFS(B16<18.5,"Underweight",AND(B16>=18.5,B16<=24.99),"Normalweight",AND(B16>=25,B16<=29.99),"Overweight",B16>=30,"Obesity")} -> Obesity | J16: {=_xlfn.IFS(C16<5.7,"Normal",AND(C16>=5.7,C16<=6.49),"Prediabetes",C16>=6.5,"Diabetes")} -> Diabetes
A17: Id16 | B17: 39.9 | C17: 11.32 | D17: No | E17: No | F17: No | G17: 0 | H17: Yes | I17: {=_xlfn.IFS(B17<18.5,"Underweight",AND(B17>=18.5,B17<=24.99),"Normalweight",AND(B17>=25,B17<=29.99),"Overweight",B17>=30,"Obesity")} -> Obesity | J17: {=_xlfn.IFS(C17<5.7,"Normal",AND(C17>=5.7,C17<=6.49),"Prediabetes",C17>=6.5,"Diabetes")} -> Diabetes
A18: Id17 | B18: 33.8 | C18: 7.67 | D18: No | E18: No | F18: No | G18: 3 | H18: Yes | I18: {=_xlfn.IFS(B18<18.5,"Underweight",AND(B18>=18.5,B18<=24.99),"Normalweight",AND(B18>=25,B18<=29.99),"Overweight",B18>=30,"Obesity")} -> Obesity | J18: {=_xlfn.IFS(C18<5.7,"Normal",AND(C18>=5.7,C18<=6.49),"Prediabetes",C18>=6.5,"Diabetes")} -> Diabetes
A19: Id18 | B19: 36.765 | C19: 7.29 | D19: Yes | E19: No | F19: Yes | G19: 1 | H19: Yes | I19: {=_xlfn.IFS(B19<18.5,"Underweight",AND(B19>=18.5,B19<=24.99),"Normalweight",AND(B19>=25,B19<=29.99),"Overweight",B19>=30,"Obesity")} -> Obesity | J19: {=_xlfn.IFS(C19<5.7,"Normal",AND(C19>=5.7,C19<=6.49),"Prediabetes",C19>=6.5,"Diabetes")} -> Diabetes
... A2336: Id2335 | B2336: 17.58 | C2336: 4.51 | D2336: No | E2336: No | F2336: No | G2336: 1 | H2336: No | I2336: {=_xlfn.IFS(B2336<18.5,"Underweight",AND(B2336>=18.5,B2336<=24.99),"Normalweight",AND(B2336>=25,B2336<=29.99),"Overweight",B2336>=30,"Obesity")} -> Underweight | J2336: {=_xlfn.IFS(C2336<5.7,"Normal",AND(C2336>=5.7,C2336<=6.49),"Prediabetes",C2336>=6.5,"Diabetes")} -> Normal

Sheet Hospitalisation Details
A1: Customer ID | B1: year | C1: month | D1: date | E1: Date of Birth | F1: children | G1: charges | H1: Hospital tier | I1: City tier | J1: State ID
A2: Id2335 | B2: 1992 | C2: Jul | D2: 9 | E2: 9-Jul-1992 | F2: 0 | G2: 563.84 | H2: tier - 2 | I2: tier - 3 | J2: R1013
A3: Id2334 | B3: 1992 | C3: Nov | D3: 30 | E3: 30-Nov-1992 | F3: 0 | G3: 570.62 | H3: tier - 2 | I3: tier - 1 | J3: R1013
A4: Id2333 | B4: 1993 | C4: Jun | D4: 30 | E4: 30-Jun-1993 | F4: 0 | G4: 600 | H4: tier - 2 | I4: tier - 1 | J4: R1013 | O4: tier - 1 | P4: =COUNTIF($I$2:$I$2344,O4) -> 734
A5: Id2332 | B5: 1992 | C5: Sep | D5: 13 | E5: 13-Sep-1992 | F5: 0 | G5: 604.54 | H5: tier - 3 | I5: tier - 3 | J5: R1013 | O5: tier - 2 | P5: =COUNTIF($I$2:$I$2344,O5) -> 813
A6: Id2331 | B6: 1998 | C6: Jul | D6: 27 | E6: 27-Jul-1998 | F6: 0 | G6: 637.26 | H6: tier - 3 | I6: tier - 3 | J6: R1013 | O6: tier - 3 | P6: =COUNTIF($I$2:$I$2344,O6) -> 796
A7: Id2330 | B7: 2001 | C7: Nov | D7: 20 | E7: 20-Nov-2001 | F7: 0 | G7: 646.14 | H7: tier - 3 | I7: tier - 3 | J7: R1012
A8: Id2329 | B8: 1993 | C8: Jun | D8: 1 | E8: 1-Jun-1993 | F8: 0 | G8: 650 | H8: tier - 3 | I8: tier - 3 | J8: R1013
A9: Id2328 | B9: 1995 | C9: Jul | D9: 4 | E9: 4-Jul-1995 | F9: 0 | G9: 650 | H9: tier - 3 | I9: tier - 3 | J9: R1013
A10: Id2327 | B10: 2002 | C10: Nov | D10: 29 | E10: 29-Nov-2002 | F10: 0 | G10: 668 | H10: tier - 3 | I10: tier - 2 | J10: R1012 | L10: =AVERAGE($B$2:$B$2344) -> 1982.8417
A11: Id2326 | B11: 1997 | C11: Nov | D11: 9 | E11: 35743 | F11: 0 | G11: 670 | H11: tier - 3 | I11: tier - 3 | J11: R1013
A12: Id2325 | B12: 2001 | C12: Sep | D12: 12 | E12: 12-Sep-2001 | F12: 0 | G12: 687.54 | H12: tier - 3 | I12: tier - 2 | J12: R1013
A13: Id2324 | B13: 1999 | C13: Dec | D13: 26 | E13: 26-Dec-1999 | F13: 0 | G13: 700 | H13: tier - 2 | I13: tier - 3 | J13: R1013 | M13: I546
A14: Id2323 | B14: 1999 | C14: Dec | D14: 14 | E14: 14-Dec-1999 | F14: 0 | G14: 722.99 | H14: tier - 3 | I14: tier - 1 | J14: R1013
A15: Id2322 | B15: 2002 | C15: Sep | D15: 19 | E15: 19-Sep-2002 | F15: 0 | G15: 750 | H15: tier - 3 | I15: tier - 1 | J15: R1012
A16: Id2321 | B16: 1993 | C16: Aug | D16: 9 | E16: 9-Aug-1993 | F16: 0 | G16: 760 | H16: tier - 3 | I16: tier - 1 | J16: R1013
A17: Id2320 | B17: 1996 | C17: Oct | D17: 22 | E17: 22-Oct-1996 | F17: 0 | G17: 760 | H17: tier - 3 | I17: tier - 3 | J17: R1013 | L17: =546 -> 546
A18: Id2319 | B18: 1993 | C18: Jun | D18: 28 | E18: 28-Jun-1993 | F18: 0 | G18: 770 | H18: tier - 3 | I18: tier - 3 | J18: R1013
A19: Id2318 | B19: 1996 | C19: Sep | D19: 18 | E19: 18-Sep-1996 | F19: 0 | G19: 770.38 | H19: tier - 3 | I19: tier - 2 | J19: R1012
A20: Id2317 | B20: 1995 | C20: Dec | D20: 7 | E20: 7-Dec-1995 | F20: 0 | G20: 773.54 | H20: tier - 3 | I20: tier - 2 | J20: R1013
A21: Id2316 | B21: 2004 | C21: Oct | D21: 7 | E21: 7-Oct-2004 | F21: 0 | G21: 830.52 | H21: tier - 3 | I21: tier - 2 | J21: R1011
A22: Id2315 | B22: 2000 | C22: Nov | D22: 18 | E22: 18-Nov-2000 | F22: 0 | G22: 865.41 | H22: tier - 3 | I22: tier - 1 | J22: R1013
A23: Id2314 | B23: 1993 | C23: Nov | D23: 27 | E23: 27-Nov-1993 | F23: 0 | G23: 896.21 | H23: tier - 3 | I23: tier - 1 | J23: R1013
A24: Id2313 | B24: 1994 | C24: Oct | D24: 30 | E24: 30-Oct-1994 | F24: 0 | G24: 915.07 | H24: tier - 3 | I24: tier - 1 | J24: R1013
A25: Id2312 | B25: 1995 | C25: Oct | D25: 28 | E25: 28-Oct-1995 | F25: 0 | G25: 928.59 | H25: tier - 3 | I25: tier - 1 | J25: R1013
A26: Id2311 | B26: 2001 | C26: Aug | D26: 19 | E26: 19-Aug-2001 | F26: 0 | G26: 964.71 | H26: tier - 3 | I26: tier - 2 | J26: R1013
A27: Id2310 | B27: 1994 | C27: Nov | D27: 22 | E27: 22-Nov-1994 | F27: 0 | G27: 1006.65 | H27: tier - 3 | I27: tier - 2 | J27: R1013
A28: Id2309 | B28: 2000 | C28: Oct | D28: 9 | E28: 9-Oct-2000 | F28: 0 | G28: 1012 | H28: tier - 3 | I28: tier - 2 | J28: R1013
A29: Id2308 | B29: 1999 | C29: Aug | D29: 5 | E29: 5-Aug-1999 | F29: 0 | G29: 1019 | H29: tier - 3 | I29: tier - 2 | J29: R1013
... A545: Id1794 | B545: 1981 | C545: Jul | D545: 3 | E545: 27-Jun-2002 | F545: 1 | G545: 4827.1 | H545: tier - 2 | I545: tier - 1 | J545: R1013
A546: Id1793 | B546: 1995 | C546: Dec | D546: 1 | E546: 11-Dec-2000 | F546: 3 | G546: 4827.9 | H546: tier - 1 | I546: tier - 2 | J546: =J545 -> R1013
A547: Id1792 | B547: 2002 | C547: Jun | D547: 27 | E547: 10-Sep-1992 | F547: 5 | G547: 4830.63 | H547: tier - 2 | I547: tier - 1 | J547: R1011
A548: Id1791 | B548: 2000 | C548: Dec | D548: 11 | E548: 15-Oct-1984 | F548: 0 | G548: 4835.43 | H548: tier - 2 | I548: tier - 2 | J548: R1021
A549: Id1790 | B549: 1992 | C549: Sep | D549: 10 | E549: 29-Sep-1995 | F549: 3 | G549: 4837.58 | H549: tier - 3 | I549: tier - 2 | J549: R1013
A550: Id1789 | B550: 1984 | C550: Oct | D550: 15 | E550: 13-Dec-1979 | F550: 3 | G550: 4839.18 | H550: tier - 2 | I550: tier - 1 | J550: R1012
A551: Id1788 | B551: 1995 | C551: Sep | D551: 29 | E551: 11-Sep-1974 | F551: 0 | G551: 4840.95 | H551: tier - 2 | I551: tier - 1 | J551: R1021
A552: Id1787 | B552: 1979 | C552: Dec | D552: 13 | E552: 7-Jun-2001 | F552: 2 | G552: 4843.79 | H552: tier - 2 | I552: tier - 3 | J552: R1013
A553: Id1786 | B553: 1974 | C553: Sep | D553: 11 | E553: 27-Dec-1995 | F553: 0 | G553: 4844.67 | H553: tier - 2 | I553: tier - 2 | J553: R1013
A554: Id1785 | B554: 2001 | C554: Jun | D554: 7 | E554: 1-Sep-1989 | F554: 0 | G554: 4846.53 | H554: tier - 2 | I554: tier - 3 | J554: R1021
A555: Id1784 | B555: 1995 | C555: Dec | D555: 27 | E555: 29-Sep-1997 | F555: 3 | G555: 4846.92 | H555: tier - 2 | I555: tier - 3 | J555: R1017
...

Sheet healthcare
A1: Customer ID | B1: First Name | C1: BMI | D1: HBA1C | E1: Heart Issues | F1: Any Transplants | G1: Cancer history | H1: NumberOfMajorSurgeries | I1: Smoker | J1: Weight Status | K1: Diabetes Status | L1: Charges | M1: Hospital tier | N1: City tier | O1: State ID | P1: Age
A2: Id1 | B2: =VLOOKUP('Customer Names'!A2,'Customer Names'!$A$1:$E$2336,4,FALSE) -> Ms. Kelly | C2: =VLOOKUP(Table2[[#This Row],[Customer ID]],Table2[#All],2,FALSE) -> 47.41 | D2: =VLOOKUP(Table2[[#This Row],[Customer ID]],Table2[#All],3,FALSE) -> 7.47 | E2: =VLOOKUP(Table2[[#This Row],[Customer ID]],Table2[#All],4,FALSE) -> No | F2: =VLOOKUP(Table2[[#This Row],[Customer ID]],Table2[#All],5,FALSE) -> No | G2: =VLOOKUP(Table2[[#This Row],[Customer ID]],Table2[#All],6,FALSE) -> No | H2: =VLOOKUP(Table2[[#This Row],[Customer ID]],Table2[#All],7,FALSE) -> 0 | I2: =VLOOKUP(Table2[[#This Row],[Customer ID]],Table2[#All],8,FALSE) -> Yes | J2: =VLOOKUP(Table2[[#This Row],[Customer ID]],Table2[#All],9,FALSE) -> Obesity | K2: =VLOOKUP(Table2[[#This Row],[Customer ID]],Table2[#All],10,FALSE) -> Diabetes
A3: Id2 | B3: =VLOOKUP('Customer Names'!A3,'Customer Names'!$A$1:$E$2336,4,FALSE) -> Mr. Matthew D | C3: =VLOOKUP(Table2[[#This Row],[Customer ID]],Table2[#All],2,FALSE) -> 30.36 | D3: =VLOOKUP(Table2[[#This Row],[Customer ID]],Table2[#All],3,FALSE) -> 5.77 | E3: =VLOOKUP(Table2[[#This Row],[Customer ID]],Table2[#All],4,FALSE) -> No | F3: =VLOOKUP(Table2[[#This Row],[Customer ID]],Table2[#All],5,FALSE) -> No | G3: =VLOOKUP(Table2[[#This Row],[Customer ID]],Table2[#All],6,FALSE) -> No | H3: =VLOOKUP(Table2[[#This Row],[Customer ID]],Table2[#All],7,FALSE) -> 0 | I3: =VLOOKUP(Table2[[#This Row],[Customer ID]],Table2[#All],8,FALSE) -> Yes | J3: =VLOOKUP(Table2[[#This Row],[Customer ID]],Table2[#All],9,FALSE) -> Obesity | K3: =VLOOKUP(Table2[[#This Row],[Customer ID]],Table2[#All],10,FALSE) -> Prediabetes
A4: Id3 | B4: =VLOOKUP('Customer Names'!A4,'Customer Names'!$A$1:$E$2336,4,FALSE) -> Mr. Phil | C4: =VLOOKUP(Table2[[#This Row],[Customer ID]],Table2[#All],2,FALSE) -> 34.485 | D4: =VLOOKUP(Table2[[#This Row],[Customer ID]],Table2[#All],3,FALSE) -> 11.87 | E4: =VLOOKUP(Table2[[#This Row],[Customer ID]],Table2[#All],4,FALSE) -> Yes | F4: =VLOOKUP(Table2[[#This Row],[Customer ID]],Table2[#All],5,FALSE) -> No | G4: =VLOOKUP(Table2[[#This Row],[Customer ID]],Table2[#All],6,FALSE) -> No | H4: =VLOOKUP(Table2[[#This Row],[Customer ID]],Table2[#All],7,FALSE) -> 2 | I4: =VLOOKUP(Table2[[#This Row],[Customer ID]],Table2[#All],8,FALSE) -> Yes | J4: =VLOOKUP(Table2[[#This Row],[Customer ID]],Table2[#All],9,FALSE) -> Obesity | K4: =VLOOKUP(Table2[[#This Row],[Customer ID]],Table2[#All],10,FALSE) -> Diabetes
A5: Id4 | B5: =VLOOKUP('Customer Names'!A5,'Customer Names'!$A$1:$E$2336,4,FALSE) -> Ms. Kelsey | C5: =VLOOKUP(Table2[[#This Row],[Customer ID]],Table2[#All],2,FALSE) -> 38.095 | D5: =VLOOKUP(Table2[[#This Row],[Customer ID]],Table2[#All],3,FALSE) -> 6.05 | E5: =VLOOKUP(Table2[[#This Row],[Customer ID]],Table2[#All],4,FALSE) -> No | F5: =VLOOKUP(Table2[[#This Row],[Customer ID]],Table2[#All],5,FALSE) -> No | G5: =VLOOKUP(Table2[[#This Row],[Customer ID]],Table2[#All],6,FALSE) -> No | H5: =VLOOKUP(Table2[[#This Row],[Customer ID]],Table2[#All],7,FALSE) -> 0 | I5: =VLOOKUP(Table2[[#This Row],[Customer ID]],Table2[#All],8,FALSE) -> Yes | J5: =VLOOKUP(Table2[[#This Row],[Customer ID]],Table2[#All],9,FALSE) -> Obesity | K5: =VLOOKUP(Table2[[#This Row],[Customer ID]],Table2[#All],10,FALSE) -> Prediabetes
A6: Id5 | B6: =VLOOKUP('Customer Names'!A6,'Customer Names'!$A$1:$E$2336,4,FALSE) -> Ms. Kristyn | C6: =VLOOKUP(Table2[[#This Row],[Customer ID]],Table2[#All],2,FALSE) -> 35.53 | D6: =VLOOKUP(Table2[[#This Row],[Customer ID]],Table2[#All],3,FALSE) -> 5.45 | E6: =VLOOKUP(Table2[[#This Row],[Customer ID]],Table2[#All],4,FALSE) -> No | F6: =VLOOKUP(Table2[[#This Row],[Customer ID]],Table2[#All],5,FALSE) -> No | G6: =VLOOKUP(Table2[[#This Row],[Customer ID]],Table2[#All],6,FALSE) -> No | H6: =VLOOKUP(Table2[[#This Row],[Customer ID]],Table2[#All],7,FALSE) -> 0 | I6: =VLOOKUP(Table2[[#This Row],[Customer ID]],Table2[#All],8,FALSE) -> Yes | J6: =VLOOKUP(Table2[[#This Row],[Customer ID]],Table2[#All],9,FALSE) -> Obesity | K6: =VLOOKUP(Table2[[#This Row],[Customer ID]],Table2[#All],10,FALSE) -> Normal
A7: Id6 | B7: =VLOOKUP('Customer Names'!A7,'Customer Names'!$A$1:$E$2336,4,FALSE) -> Mr. Russell B. | C7: =VLOOKUP(Table2[[#This Row],[Customer ID]],Table2[#All],2,FALSE) -> 32.8 | D7: =VLOOKUP(Table2[[#This Row],[Customer ID]],Table2[#All],3,FALSE) -> 6.59 | E7: =VLOOKUP(Table2[[#This Row],[Customer ID]],Table2[#All],4,FALSE) -> No | F7: =VLOOKUP(Table2[[#This Row],[Customer ID]],Table2[#All],5,FALSE) -> No | G7: =VLOOKUP(Table2[[#This Row],[Customer ID]],Table2[#All],6,FALSE) -> No | H7: =VLOOKUP(Table2[[#This Row],[Customer ID]],Table2[#All],7,FALSE) -> 0 | I7: =VLOOKUP(Table2[[#This Row],[Customer ID]],Table2[#All],8,FALSE) -> Yes | J7: =VLOOKUP(Table2[[#This Row],[Customer ID]],Table2[#All],9,FALSE) -> Obesity | K7: =VLOOKUP(Table2[[#This Row],[Customer ID]],Table2[#All],10,FALSE) -> Diabetes
A8: Id7 | B8: =VLOOKUP('Customer Names'!A8,'Customer Names'!$A$1:$E$2336,4,FALSE) -> Mr. Scott | C8: =VLOOKUP(Table2[[#This Row],[Customer ID]],Table2[#All],2,FALSE) -> 36.4 | D8: =VLOOKUP(Table2[[#This Row],[Customer ID]],Table2[#All],3,FALSE) -> 6.07 | E8: =VLOOKUP(Table2[[#This Row],[Customer ID]],Table2[#All],4,FALSE) -> No | F8: =VLOOKUP(Table2[[#This Row],[Customer ID]],Table2[#All],5,FALSE) -> No | G8: =VLOOKUP(Table2[[#This Row],[Customer ID]],Table2[#All],6,FALSE) -> No | H8: =VLOOKUP(Table2[[#This Row],[Customer ID]],Table2[#All],7,FALSE) -> 0 | I8: =VLOOKUP(Table2[[#This Row],[Customer ID]],Table2[#All],8,FALSE) -> Yes | J8: =VLOOKUP(Table2[[#This Row],[Customer ID]],Table2[#All],9,FALSE) -> Obesity | K8: =VLOOKUP(Table2[[#This Row],[Customer ID]],Table2[#All],10,FALSE) -> Prediabetes
A9: Id8 | B9: =VLOOKUP('Customer Names'!A9,'Customer Names'!$A$1:$E$2336,4,FALSE) -> Mr. Stephen | C9: =VLOOKUP(Table2[[#This Row],[Customer ID]],Table2[#All],2,FALSE) -> 36.96 | D9: =VLOOKUP(Table2[[#This Row],[Customer ID]],Table2[#All],3,FALSE) -> 7.93 | E9: =VLOOKUP(Table2[[#This Row],[Customer ID]],Table2[#All],4,FALSE) -> No | F9: =VLOOKUP(Table2[[#This Row],[Customer ID]],Table2[#All],5,FALSE) -> No | G9: =VLOOKUP(Table2[[#This Row],[Customer ID]],Table2[#All],6,FALSE) -> No | H9: =VLOOKUP(Table2[[#This Row],[Customer ID]],Table2[#All],7,FALSE) -> 3 | I9: =VLOOKUP(Table2[[#This Row],[Customer ID]],Table2[#All],8,FALSE) -> Yes | J9: =VLOOKUP(Table2[[#This Row],[Customer ID]],Table2[#All],9,FALSE) -> Obesity | K9: =VLOOKUP(Table2[[#This Row],[Customer ID]],Table2[#All],10,FALSE) -> Diabetes
A10: Id9 | B10: =VLOOKUP('Customer Names'!A10,'Customer Names'!$A$1:$E$2336,4,FALSE) -> Mr. Patrick R. | C10: =VLOOKUP(Table2[[#This Row],[Customer ID]],Table2[#All],2,FALSE) -> 41.14 | D10: =VLOOKUP(Table2[[#This Row],[Customer ID]],Table2[#All],3,FALSE) -> 9.58 | E10: =VLOOKUP(Table2[[#This Row],[Customer ID]],Table2[#All],4,FALSE) -> Yes | F10: =VLOOKUP(Table2[[#This Row],[Customer ID]],Table2[#All],5,FALSE) -> No | G10: =VLOOKUP(Table2[[#This Row],[Customer ID]],Table2[#All],6,FALSE) -> Yes | H10: =VLOOKUP(Table2[[#This Row],[Customer ID]],Table2[#All],7,FALSE) -> 1 | I10: =VLOOKUP(Table2[[#This Row],[Customer ID]],Table2[#All],8,FALSE) -> Yes | J10: =VLOOKUP(Table2[[#This Row],[Customer ID]],Table2[#All],9,FALSE) -> Obesity | K10: =VLOOKUP(Table2[[#This Row],[Customer ID]],Table2[#All],10,FALSE) -> Diabetes
A11: Id10 | B11: =VLOOKUP('Customer Names'!A11,'Customer Names'!$A$1:$E$2336,4,FALSE) -> Ms. Brooke N. | C11: =VLOOKUP(Table2[[#This Row],[Customer ID]],Table2[#All],2,FALSE) -> 38.06 | D11: =VLOOKUP(Table2[[#This Row],[Customer ID]],Table2[#All],3,FALSE) -> 10.79 | E11: =VLOOKUP(Table2[[#This Row],[Customer ID]],Table2[#All],4,FALSE) -> No | F11: =VLOOKUP(Table2[[#This Row],[Customer ID]],Table2[#All],5,FALSE) -> No | G11: =VLOOKUP(Table2[[#This Row],[Customer ID]],Table2[#All],6,FALSE) -> No | H11: =VLOOKUP(Table2[[#This Row],[Customer ID]],Table2[#All],7,FALSE) -> 0 | I11: =VLOOKUP(Table2[[#This Row],[Customer ID]],Table2[#All],8,FALSE) -> Yes | J11: =VLOOKUP(Table2[[#This Row],[Customer ID]],Table2[#All],9,FALSE) -> Obesity | K11: =VLOOKUP(Table2[[#This Row],[Customer ID]],Table2[#All],10,FALSE) -> Diabetes
A12: Id11 | B12: =VLOOKUP('Customer Names'!A12,'Customer Names'!$A$1:$E$2336,4,FALSE) -> Ms. Paola Andrea | C12: =VLOOKUP(Table2[[#This Row],[Customer ID]],Table2[#All],2,FALSE) -> 37.7 | D12: =VLOOKUP(Table2[[#This Row],[Customer ID]],Table2[#All],3,FALSE) -> 5.96 | E12: =VLOOKUP(Table2[[#This Row],[Customer ID]],Table2[#All],4,FALSE) -> Yes | F12: =VLOOKUP(Table2[[#This Row],[Customer ID]],Table2[#All],5,FALSE) -> No | G12: =VLOOKUP(Table2[[#This Row],[Customer ID]],Table2[#All],6,FALSE) -> No | H12: =VLOOKUP(Table2[[#This Row],[Customer ID]],Table2[#All],7,FALSE) -> 2 | I12: =VLOOKUP(Table2[[#This Row],[Customer ID]],Table2[#All],8,FALSE) -> Yes | J12: =VLOOKUP(Table2[[#This Row],[Customer ID]],Table2[#All],9,FALSE) -> Obesity | K12: =VLOOKUP(Table2[[#This Row],[Customer ID]],Table2[#All],10,FALSE) -> Prediabetes
A13: Id12 | B13: =VLOOKUP('Customer Names'!A13,'Customer Names'!$A$1:$E$2336,4,FALSE) -> Mr. David | C13: =VLOOKUP(Table2[[#This Row],[Customer ID]],Table2[#All],2,FALSE) -> 42.13 | D13: =VLOOKUP(Table2[[#This Row],[Customer ID]],Table2[#All],3,FALSE) -> 11.9 | E13: =VLOOKUP(Table2[[#This Row],[Customer ID]],Table2[#All],4,FALSE) -> No | F13: =VLOOKUP(Table2[[#This Row],[Customer ID]],Table2[#All],5,FALSE) -> No | G13: =VLOOKUP(Table2[[#This Row],[Customer ID]],Table2[#All],6,FALSE) -> No | H13: =VLOOKUP(Table2[[#This Row],[Customer ID]],Table2[#All],7,FALSE) -> 0 | I13: =VLOOKUP(Table2[[#This Row],[Customer ID]],Table2[#All],8,FALSE) -> Yes | J13: =VLOOKUP(Table2[[#This Row],[Customer ID]],Table2[#All],9,FALSE) -> Obesity | K13: =VLOOKUP(Table2[[#This Row],[Customer ID]],Table2[#All],10,FALSE) -> Diabetes
... A2336: Id2335 | B2336: =VLOOKUP('Customer Names'!A2336,'Customer Names'!$A$1:$E$2336,4,FALSE) -> Mr. Aaron K | C2336: =VLOOKUP(Table2[[#This Row],[Customer ID]],Table2[#All],2,FALSE) -> 17.58 | D2336: =VLOOKUP(Table2[[#This Row],[Customer ID]],Table2[#All],3,FALSE) -> 4.51 | E2336: =VLOOKUP(Table2[[#This Row],[Customer ID]],Table2[#All],4,FALSE) -> No | F2336: =VLOOKUP(Table2[[#This Row],[Customer ID]],Table2[#All],5,FALSE) -> No | G2336: =VLOOKUP(Table2[[#This Row],[Customer ID]],Table2[#All],6,FALSE) -> No | H2336: =VLOOKUP(Table2[[#This Row],[Customer ID]],Table2[#All],7,FALSE) -> 1 | I2336: =VLOOKUP(Table2[[#This Row],[Customer ID]],Table2[#All],8,FALSE) -> No | J2336: =VLOOKUP(Table2[[#This Row],[Customer ID]],Table2[#All],9,FALSE) -> Underweight | K2336: =VLOOKUP(Table2[[#This Row],[Customer ID]],Table2[#All],10,FALSE) -> Normal
